[2025-05-16T08:16:52.005+0000] {local_task_job_runner.py:120} INFO - ::group::Pre task execution logs
[2025-05-16T08:16:54.225+0000] {taskinstance.py:2076} INFO - Dependencies all met for dep_context=non-requeueable deps ti=<TaskInstance: random_user_pipeline.insert_postgres manual__2025-05-16T08:16:43.917426+00:00 [queued]>
[2025-05-16T08:16:54.235+0000] {taskinstance.py:2076} INFO - Dependencies all met for dep_context=requeueable deps ti=<TaskInstance: random_user_pipeline.insert_postgres manual__2025-05-16T08:16:43.917426+00:00 [queued]>
[2025-05-16T08:16:54.236+0000] {taskinstance.py:2306} INFO - Starting attempt 1 of 2
[2025-05-16T08:16:54.251+0000] {taskinstance.py:2330} INFO - Executing <Task(PythonOperator): insert_postgres> on 2025-05-16 08:16:43.917426+00:00
[2025-05-16T08:16:54.257+0000] {standard_task_runner.py:90} INFO - Running: ['airflow', 'tasks', 'run', 'random_user_pipeline', 'insert_***', 'manual__2025-05-16T08:16:43.917426+00:00', '--job-id', '265', '--raw', '--subdir', 'DAGS_FOLDER/random_user_pipeline.py', '--cfg-path', '/tmp/tmpgq3c9cbp']
[2025-05-16T08:16:54.259+0000] {logging_mixin.py:188} WARNING - /home/airflow/.local/lib/python3.12/site-packages/airflow/task/task_runner/standard_task_runner.py:61 DeprecationWarning: This process (pid=224) is multi-threaded, use of fork() may lead to deadlocks in the child.
[2025-05-16T08:16:54.259+0000] {standard_task_runner.py:91} INFO - Job 265: Subtask insert_***
[2025-05-16T08:16:54.260+0000] {standard_task_runner.py:63} INFO - Started process 225 to run task
[2025-05-16T08:16:57.398+0000] {task_command.py:426} INFO - Running <TaskInstance: random_user_pipeline.insert_postgres manual__2025-05-16T08:16:43.917426+00:00 [running]> on host ae62328e3add
[2025-05-16T08:16:58.455+0000] {taskinstance.py:2648} INFO - Exporting env vars: AIRFLOW_CTX_DAG_EMAIL='papala.ramesh@quation.in,smilesoframs@gmail.com,ramesh.rams333@gmail.com' AIRFLOW_CTX_DAG_OWNER='airflow' AIRFLOW_CTX_DAG_ID='random_user_pipeline' AIRFLOW_CTX_TASK_ID='insert_***' AIRFLOW_CTX_EXECUTION_DATE='2025-05-16T08:16:43.917426+00:00' AIRFLOW_CTX_TRY_NUMBER='1' AIRFLOW_CTX_DAG_RUN_ID='manual__2025-05-16T08:16:43.917426+00:00'
[2025-05-16T08:16:58.456+0000] {taskinstance.py:430} INFO - ::endgroup::
[2025-05-16T08:16:58.469+0000] {taskinstance.py:441} INFO - ::group::Post task execution logs
[2025-05-16T08:16:58.469+0000] {taskinstance.py:2905} ERROR - Task failed with exception
Traceback (most recent call last):
  File "/home/airflow/.local/lib/python3.12/site-packages/airflow/models/taskinstance.py", line 465, in _execute_task
    result = _execute_callable(context=context, **execute_callable_kwargs)
             ^^^^^^^^^^^^^^^^^^^^^^^^^^^^^^^^^^^^^^^^^^^^^^^^^^^^^^^^^^^^^
  File "/home/airflow/.local/lib/python3.12/site-packages/airflow/models/taskinstance.py", line 432, in _execute_callable
    return execute_callable(context=context, **execute_callable_kwargs)
           ^^^^^^^^^^^^^^^^^^^^^^^^^^^^^^^^^^^^^^^^^^^^^^^^^^^^^^^^^^^^
  File "/home/airflow/.local/lib/python3.12/site-packages/airflow/models/baseoperator.py", line 401, in wrapper
    return func(self, *args, **kwargs)
           ^^^^^^^^^^^^^^^^^^^^^^^^^^^
  File "/home/airflow/.local/lib/python3.12/site-packages/airflow/operators/python.py", line 235, in execute
    return_value = self.execute_callable()
                   ^^^^^^^^^^^^^^^^^^^^^^^
  File "/home/airflow/.local/lib/python3.12/site-packages/airflow/operators/python.py", line 252, in execute_callable
    return self.python_callable(*self.op_args, **self.op_kwargs)
           ^^^^^^^^^^^^^^^^^^^^^^^^^^^^^^^^^^^^^^^^^^^^^^^^^^^^^
  File "/opt/airflow/dags/storage/postgres_loader/write_to_postgres.py", line 10, in write_to_postgres
    if isinstancekkk(data, str):
       ^^^^^^^^^^^^^
NameError: name 'isinstancekkk' is not defined. Did you mean: 'isinstance'?
[2025-05-16T08:16:58.641+0000] {taskinstance.py:1206} INFO - Marking task as UP_FOR_RETRY. dag_id=random_user_pipeline, task_id=insert_***, run_id=manual__2025-05-16T08:16:43.917426+00:00, execution_date=20250516T081643, start_date=20250516T081654, end_date=20250516T081658
[2025-05-16T08:16:58.658+0000] {standard_task_runner.py:110} ERROR - Failed to execute job 265 for task insert_*** (name 'isinstancekkk' is not defined; 225)
[2025-05-16T08:16:58.699+0000] {local_task_job_runner.py:240} INFO - Task exited with return code 1
[2025-05-16T08:16:58.882+0000] {taskinstance.py:3503} INFO - 0 downstream tasks scheduled from follow-on schedule check
[2025-05-16T08:16:58.884+0000] {local_task_job_runner.py:222} INFO - ::endgroup::
