[2025-04-29T06:45:06.622+0000] {local_task_job_runner.py:120} INFO - ::group::Pre task execution logs
[2025-04-29T06:45:11.746+0000] {taskinstance.py:2076} INFO - Dependencies all met for dep_context=non-requeueable deps ti=<TaskInstance: random_user_pipeline.insert_postgres scheduled__2025-04-28T16:59:00+00:00 [queued]>
[2025-04-29T06:45:11.781+0000] {taskinstance.py:2076} INFO - Dependencies all met for dep_context=requeueable deps ti=<TaskInstance: random_user_pipeline.insert_postgres scheduled__2025-04-28T16:59:00+00:00 [queued]>
[2025-04-29T06:45:11.788+0000] {taskinstance.py:2306} INFO - Starting attempt 1 of 2
[2025-04-29T06:45:12.112+0000] {taskinstance.py:2330} INFO - Executing <Task(PythonOperator): insert_postgres> on 2025-04-28 16:59:00+00:00
[2025-04-29T06:45:12.140+0000] {standard_task_runner.py:90} INFO - Running: ['airflow', 'tasks', 'run', 'random_user_pipeline', 'insert_***', 'scheduled__2025-04-28T16:59:00+00:00', '--job-id', '119', '--raw', '--subdir', 'DAGS_FOLDER/random_user_pipeline.py', '--cfg-path', '/tmp/tmpdyaqtb3h']
[2025-04-29T06:45:12.157+0000] {logging_mixin.py:188} WARNING - /home/airflow/.local/lib/python3.12/site-packages/airflow/task/task_runner/standard_task_runner.py:61 DeprecationWarning: This process (pid=251) is multi-threaded, use of fork() may lead to deadlocks in the child.
[2025-04-29T06:45:12.171+0000] {standard_task_runner.py:91} INFO - Job 119: Subtask insert_***
[2025-04-29T06:45:12.177+0000] {standard_task_runner.py:63} INFO - Started process 264 to run task
[2025-04-29T06:45:27.283+0000] {task_command.py:426} INFO - Running <TaskInstance: random_user_pipeline.insert_postgres scheduled__2025-04-28T16:59:00+00:00 [running]> on host 04b4fc26656e
[2025-04-29T06:55:30.589+0000] {local_task_job_runner.py:214} ERROR - Heartbeat time limit exceeded!
[2025-04-29T06:55:30.590+0000] {local_task_job_runner.py:222} INFO - ::endgroup::
[2025-04-29T06:55:30.600+0000] {process_utils.py:132} INFO - Sending 15 to group 264. PIDs of all processes in the group: [264]
[2025-04-29T06:55:30.608+0000] {process_utils.py:87} INFO - Sending the signal 15 to group 264
[2025-04-29T06:55:33.551+0000] {taskinstance.py:2611} ERROR - Received SIGTERM. Terminating subprocesses.
[2025-04-29T06:55:41.782+0000] {taskinstance.py:2905} ERROR - Task failed with exception
Traceback (most recent call last):
  File "/home/airflow/.local/lib/python3.12/site-packages/airflow/models/taskinstance.py", line 2479, in _run_raw_task
    self._execute_task_with_callbacks(context, test_mode, session=session)
  File "/home/airflow/.local/lib/python3.12/site-packages/airflow/models/taskinstance.py", line 2638, in _execute_task_with_callbacks
    RenderedTaskInstanceFields.delete_old_records(self.task_id, self.dag_id)
  File "/home/airflow/.local/lib/python3.12/site-packages/airflow/utils/session.py", line 79, in wrapper
    return func(*args, session=session, **kwargs)
           ^^^^^^^^^^^^^^^^^^^^^^^^^^^^^^^^^^^^^^
  File "/home/airflow/.local/lib/python3.12/site-packages/airflow/models/renderedtifields.py", line 235, in delete_old_records
    cls._do_delete_old_records(
  File "/home/airflow/.local/lib/python3.12/site-packages/airflow/utils/retries.py", line 89, in wrapped_function
    for attempt in run_with_db_retries(max_retries=retries, logger=logger, **retry_kwargs):
  File "/home/airflow/.local/lib/python3.12/site-packages/tenacity/__init__.py", line 435, in __iter__
    do = self.iter(retry_state=retry_state)
         ^^^^^^^^^^^^^^^^^^^^^^^^^^^^^^^^^^
  File "/home/airflow/.local/lib/python3.12/site-packages/tenacity/__init__.py", line 368, in iter
    result = action(retry_state)
             ^^^^^^^^^^^^^^^^^^^
  File "/home/airflow/.local/lib/python3.12/site-packages/tenacity/__init__.py", line 390, in <lambda>
    self._add_action_func(lambda rs: rs.outcome.result())
                                     ^^^^^^^^^^^^^^^^^^^
  File "/usr/local/lib/python3.12/concurrent/futures/_base.py", line 449, in result
    return self.__get_result()
           ^^^^^^^^^^^^^^^^^^^
  File "/usr/local/lib/python3.12/concurrent/futures/_base.py", line 401, in __get_result
    raise self._exception
  File "/home/airflow/.local/lib/python3.12/site-packages/airflow/utils/retries.py", line 98, in wrapped_function
    return func(*args, **kwargs)
           ^^^^^^^^^^^^^^^^^^^^^
  File "/home/airflow/.local/lib/python3.12/site-packages/airflow/models/renderedtifields.py", line 269, in _do_delete_old_records
    session.execute(stmt)
  File "/home/airflow/.local/lib/python3.12/site-packages/sqlalchemy/orm/session.py", line 1716, in execute
    conn = self._connection_for_bind(bind)
           ^^^^^^^^^^^^^^^^^^^^^^^^^^^^^^^
  File "/home/airflow/.local/lib/python3.12/site-packages/sqlalchemy/orm/session.py", line 1555, in _connection_for_bind
    return self._transaction._connection_for_bind(
           ^^^^^^^^^^^^^^^^^^^^^^^^^^^^^^^^^^^^^^^
  File "/home/airflow/.local/lib/python3.12/site-packages/sqlalchemy/orm/session.py", line 750, in _connection_for_bind
    conn = bind.connect()
           ^^^^^^^^^^^^^^
  File "/home/airflow/.local/lib/python3.12/site-packages/sqlalchemy/future/engine.py", line 412, in connect
    return super(Engine, self).connect()
           ^^^^^^^^^^^^^^^^^^^^^^^^^^^^^
  File "/home/airflow/.local/lib/python3.12/site-packages/sqlalchemy/engine/base.py", line 3325, in connect
    return self._connection_cls(self, close_with_result=close_with_result)
           ^^^^^^^^^^^^^^^^^^^^^^^^^^^^^^^^^^^^^^^^^^^^^^^^^^^^^^^^^^^^^^^
  File "/home/airflow/.local/lib/python3.12/site-packages/sqlalchemy/engine/base.py", line 96, in __init__
    else engine.raw_connection()
         ^^^^^^^^^^^^^^^^^^^^^^^
  File "/home/airflow/.local/lib/python3.12/site-packages/sqlalchemy/engine/base.py", line 3404, in raw_connection
    return self._wrap_pool_connect(self.pool.connect, _connection)
           ^^^^^^^^^^^^^^^^^^^^^^^^^^^^^^^^^^^^^^^^^^^^^^^^^^^^^^^
  File "/home/airflow/.local/lib/python3.12/site-packages/sqlalchemy/engine/base.py", line 3371, in _wrap_pool_connect
    return fn()
           ^^^^
  File "/home/airflow/.local/lib/python3.12/site-packages/sqlalchemy/pool/base.py", line 327, in connect
    return _ConnectionFairy._checkout(self)
           ^^^^^^^^^^^^^^^^^^^^^^^^^^^^^^^^
  File "/home/airflow/.local/lib/python3.12/site-packages/sqlalchemy/pool/base.py", line 894, in _checkout
    fairy = _ConnectionRecord.checkout(pool)
            ^^^^^^^^^^^^^^^^^^^^^^^^^^^^^^^^
  File "/home/airflow/.local/lib/python3.12/site-packages/sqlalchemy/pool/base.py", line 493, in checkout
    rec = pool._do_get()
          ^^^^^^^^^^^^^^
  File "/home/airflow/.local/lib/python3.12/site-packages/sqlalchemy/pool/impl.py", line 256, in _do_get
    return self._create_connection()
           ^^^^^^^^^^^^^^^^^^^^^^^^^
  File "/home/airflow/.local/lib/python3.12/site-packages/sqlalchemy/pool/base.py", line 273, in _create_connection
    return _ConnectionRecord(self)
           ^^^^^^^^^^^^^^^^^^^^^^^
  File "/home/airflow/.local/lib/python3.12/site-packages/sqlalchemy/pool/base.py", line 388, in __init__
    self.__connect()
  File "/home/airflow/.local/lib/python3.12/site-packages/sqlalchemy/pool/base.py", line 690, in __connect
    with util.safe_reraise():
  File "/home/airflow/.local/lib/python3.12/site-packages/sqlalchemy/util/langhelpers.py", line 70, in __exit__
    compat.raise_(
  File "/home/airflow/.local/lib/python3.12/site-packages/sqlalchemy/util/compat.py", line 211, in raise_
    raise exception
  File "/home/airflow/.local/lib/python3.12/site-packages/sqlalchemy/pool/base.py", line 686, in __connect
    self.dbapi_connection = connection = pool._invoke_creator(self)
                                         ^^^^^^^^^^^^^^^^^^^^^^^^^^
  File "/home/airflow/.local/lib/python3.12/site-packages/sqlalchemy/engine/create.py", line 574, in connect
    return dialect.connect(*cargs, **cparams)
           ^^^^^^^^^^^^^^^^^^^^^^^^^^^^^^^^^^
  File "/home/airflow/.local/lib/python3.12/site-packages/sqlalchemy/engine/default.py", line 598, in connect
    return self.dbapi.connect(*cargs, **cparams)
           ^^^^^^^^^^^^^^^^^^^^^^^^^^^^^^^^^^^^^
  File "/home/airflow/.local/lib/python3.12/site-packages/psycopg2/__init__.py", line 122, in connect
    conn = _connect(dsn, connection_factory=connection_factory, **kwasync)
           ^^^^^^^^^^^^^^^^^^^^^^^^^^^^^^^^^^^^^^^^^^^^^^^^^^^^^^^^^^^^^^^
  File "/home/airflow/.local/lib/python3.12/site-packages/airflow/models/taskinstance.py", line 2613, in signal_handler
    raise AirflowTaskTerminated("Task received SIGTERM signal")
airflow.exceptions.AirflowTaskTerminated: Task received SIGTERM signal
[2025-04-29T06:55:41.810+0000] {taskinstance.py:1206} INFO - Marking task as UP_FOR_RETRY. dag_id=random_user_pipeline, task_id=insert_***, run_id=scheduled__2025-04-28T16:59:00+00:00, execution_date=20250428T165900, start_date=20250429T064511, end_date=20250429T065541
[2025-04-29T06:55:41.981+0000] {process_utils.py:80} INFO - Process psutil.Process(pid=264, status='terminated', exitcode=2, started='06:45:11') (264) terminated with exit code 2
