[2025-05-20T04:36:44.627+0000] {local_task_job_runner.py:120} INFO - ::group::Pre task execution logs
[2025-05-20T04:36:44.840+0000] {taskinstance.py:2076} INFO - Dependencies all met for dep_context=non-requeueable deps ti=<TaskInstance: random_user_pipeline.insert_postgres manual__2025-05-20T04:35:27.188770+00:00 [queued]>
[2025-05-20T04:36:44.852+0000] {taskinstance.py:2076} INFO - Dependencies all met for dep_context=requeueable deps ti=<TaskInstance: random_user_pipeline.insert_postgres manual__2025-05-20T04:35:27.188770+00:00 [queued]>
[2025-05-20T04:36:44.854+0000] {taskinstance.py:2306} INFO - Starting attempt 2 of 2
[2025-05-20T04:36:44.870+0000] {taskinstance.py:2330} INFO - Executing <Task(PythonOperator): insert_postgres> on 2025-05-20 04:35:27.188770+00:00
[2025-05-20T04:36:44.875+0000] {standard_task_runner.py:90} INFO - Running: ['airflow', 'tasks', 'run', 'random_user_pipeline', 'insert_***', 'manual__2025-05-20T04:35:27.188770+00:00', '--job-id', '315', '--raw', '--subdir', 'DAGS_FOLDER/random_user_pipeline.py', '--cfg-path', '/tmp/tmpm5g9wouk']
[2025-05-20T04:36:44.877+0000] {standard_task_runner.py:91} INFO - Job 315: Subtask insert_***
[2025-05-20T04:36:44.877+0000] {logging_mixin.py:188} WARNING - /home/airflow/.local/lib/python3.12/site-packages/airflow/task/task_runner/standard_task_runner.py:61 DeprecationWarning: This process (pid=363) is multi-threaded, use of fork() may lead to deadlocks in the child.
[2025-05-20T04:36:44.878+0000] {standard_task_runner.py:63} INFO - Started process 368 to run task
[2025-05-20T04:36:45.505+0000] {task_command.py:426} INFO - Running <TaskInstance: random_user_pipeline.insert_postgres manual__2025-05-20T04:35:27.188770+00:00 [running]> on host 01a6db3bec8d
[2025-05-20T04:36:46.533+0000] {taskinstance.py:2648} INFO - Exporting env vars: AIRFLOW_CTX_DAG_EMAIL='papala.ramesh@quation.in,smilesoframs@gmail.com,ramesh.rams333@gmail.com' AIRFLOW_CTX_DAG_OWNER='airflow' AIRFLOW_CTX_DAG_ID='random_user_pipeline' AIRFLOW_CTX_TASK_ID='insert_***' AIRFLOW_CTX_EXECUTION_DATE='2025-05-20T04:35:27.188770+00:00' AIRFLOW_CTX_TRY_NUMBER='2' AIRFLOW_CTX_DAG_RUN_ID='manual__2025-05-20T04:35:27.188770+00:00'
[2025-05-20T04:36:46.534+0000] {taskinstance.py:430} INFO - ::endgroup::
[2025-05-20T04:36:47.875+0000] {taskinstance.py:441} INFO - ::group::Post task execution logs
[2025-05-20T04:36:47.875+0000] {taskinstance.py:2905} ERROR - Task failed with exception
Traceback (most recent call last):
  File "/opt/airflow/dags/storage/postgres_loader/write_to_postgres.py", line 18, in write_to_postgres
    if isinstance(data, str):
                  ^^^^
UnboundLocalError: cannot access local variable 'data' where it is not associated with a value

During handling of the above exception, another exception occurred:

Traceback (most recent call last):
  File "/home/airflow/.local/lib/python3.12/site-packages/airflow/models/taskinstance.py", line 465, in _execute_task
    result = _execute_callable(context=context, **execute_callable_kwargs)
             ^^^^^^^^^^^^^^^^^^^^^^^^^^^^^^^^^^^^^^^^^^^^^^^^^^^^^^^^^^^^^
  File "/home/airflow/.local/lib/python3.12/site-packages/airflow/models/taskinstance.py", line 432, in _execute_callable
    return execute_callable(context=context, **execute_callable_kwargs)
           ^^^^^^^^^^^^^^^^^^^^^^^^^^^^^^^^^^^^^^^^^^^^^^^^^^^^^^^^^^^^
  File "/home/airflow/.local/lib/python3.12/site-packages/airflow/models/baseoperator.py", line 401, in wrapper
    return func(self, *args, **kwargs)
           ^^^^^^^^^^^^^^^^^^^^^^^^^^^
  File "/home/airflow/.local/lib/python3.12/site-packages/airflow/operators/python.py", line 235, in execute
    return_value = self.execute_callable()
                   ^^^^^^^^^^^^^^^^^^^^^^^
  File "/home/airflow/.local/lib/python3.12/site-packages/airflow/operators/python.py", line 252, in execute_callable
    return self.python_callable(*self.op_args, **self.op_kwargs)
           ^^^^^^^^^^^^^^^^^^^^^^^^^^^^^^^^^^^^^^^^^^^^^^^^^^^^^
  File "/opt/airflow/dags/storage/postgres_loader/write_to_postgres.py", line 76, in write_to_postgres
    if conn:
       ^^^^
UnboundLocalError: cannot access local variable 'conn' where it is not associated with a value
[2025-05-20T04:36:48.074+0000] {taskinstance.py:1206} INFO - Marking task as FAILED. dag_id=random_user_pipeline, task_id=insert_***, run_id=manual__2025-05-20T04:35:27.188770+00:00, execution_date=20250520T043527, start_date=20250520T043644, end_date=20250520T043648
[2025-05-20T04:36:48.096+0000] {logging_mixin.py:188} WARNING - /home/airflow/.local/lib/python3.12/site-packages/airflow/utils/email.py:154 RemovedInAirflow3Warning: Fetching SMTP credentials from configuration variables will be deprecated in a future release. Please set credentials using a connection instead.
[2025-05-20T04:36:48.096+0000] {email.py:271} INFO - Email alerting: attempt 1
[2025-05-20T04:36:49.566+0000] {email.py:282} INFO - Sent an alert email to ['papala.ramesh@quation.in', 'smilesoframs@gmail.com', 'ramesh.rams333@gmail.com']
[2025-05-20T04:36:51.964+0000] {standard_task_runner.py:110} ERROR - Failed to execute job 315 for task insert_*** (cannot access local variable 'conn' where it is not associated with a value; 368)
[2025-05-20T04:36:51.983+0000] {local_task_job_runner.py:240} INFO - Task exited with return code 1
[2025-05-20T04:36:52.268+0000] {local_task_job_runner.py:222} INFO - ::endgroup::
