[2025-04-28T14:36:45.820+0000] {local_task_job_runner.py:120} INFO - ::group::Pre task execution logs
[2025-04-28T14:36:46.056+0000] {taskinstance.py:2076} INFO - Dependencies all met for dep_context=non-requeueable deps ti=<TaskInstance: random_user_pipeline.fetch_random_user manual__2025-04-28T14:31:31.683770+00:00 [queued]>
[2025-04-28T14:36:46.066+0000] {taskinstance.py:2076} INFO - Dependencies all met for dep_context=requeueable deps ti=<TaskInstance: random_user_pipeline.fetch_random_user manual__2025-04-28T14:31:31.683770+00:00 [queued]>
[2025-04-28T14:36:46.067+0000] {taskinstance.py:2306} INFO - Starting attempt 2 of 2
[2025-04-28T14:36:46.083+0000] {taskinstance.py:2330} INFO - Executing <Task(PythonOperator): fetch_random_user> on 2025-04-28 14:31:31.683770+00:00
[2025-04-28T14:36:46.091+0000] {logging_mixin.py:188} WARNING - /home/airflow/.local/lib/python3.12/site-packages/airflow/task/task_runner/standard_task_runner.py:61 DeprecationWarning: This process (pid=259) is multi-threaded, use of fork() may lead to deadlocks in the child.
[2025-04-28T14:36:46.089+0000] {standard_task_runner.py:90} INFO - Running: ['airflow', 'tasks', 'run', 'random_user_pipeline', 'fetch_random_user', 'manual__2025-04-28T14:31:31.683770+00:00', '--job-id', '6', '--raw', '--subdir', 'DAGS_FOLDER/random_user_pipeline.py', '--cfg-path', '/tmp/tmpb2heqgg9']
[2025-04-28T14:36:46.092+0000] {standard_task_runner.py:63} INFO - Started process 260 to run task
[2025-04-28T14:36:46.092+0000] {standard_task_runner.py:91} INFO - Job 6: Subtask fetch_random_user
[2025-04-28T14:36:46.854+0000] {task_command.py:426} INFO - Running <TaskInstance: random_user_pipeline.fetch_random_user manual__2025-04-28T14:31:31.683770+00:00 [running]> on host 1a241f445ffb
[2025-04-28T14:36:47.797+0000] {taskinstance.py:2648} INFO - Exporting env vars: AIRFLOW_CTX_DAG_OWNER='airflow' AIRFLOW_CTX_DAG_ID='random_user_pipeline' AIRFLOW_CTX_TASK_ID='fetch_random_user' AIRFLOW_CTX_EXECUTION_DATE='2025-04-28T14:31:31.683770+00:00' AIRFLOW_CTX_TRY_NUMBER='2' AIRFLOW_CTX_DAG_RUN_ID='manual__2025-04-28T14:31:31.683770+00:00'
[2025-04-28T14:36:47.798+0000] {taskinstance.py:430} INFO - ::endgroup::
[2025-04-28T14:36:55.535+0000] {taskinstance.py:441} INFO - ::group::Post task execution logs
[2025-04-28T14:36:55.536+0000] {taskinstance.py:2905} ERROR - Task failed with exception
Traceback (most recent call last):
  File "/home/airflow/.local/lib/python3.12/site-packages/airflow/models/taskinstance.py", line 465, in _execute_task
    result = _execute_callable(context=context, **execute_callable_kwargs)
             ^^^^^^^^^^^^^^^^^^^^^^^^^^^^^^^^^^^^^^^^^^^^^^^^^^^^^^^^^^^^^
  File "/home/airflow/.local/lib/python3.12/site-packages/airflow/models/taskinstance.py", line 432, in _execute_callable
    return execute_callable(context=context, **execute_callable_kwargs)
           ^^^^^^^^^^^^^^^^^^^^^^^^^^^^^^^^^^^^^^^^^^^^^^^^^^^^^^^^^^^^
  File "/home/airflow/.local/lib/python3.12/site-packages/airflow/models/baseoperator.py", line 401, in wrapper
    return func(self, *args, **kwargs)
           ^^^^^^^^^^^^^^^^^^^^^^^^^^^
  File "/home/airflow/.local/lib/python3.12/site-packages/airflow/operators/python.py", line 235, in execute
    return_value = self.execute_callable()
                   ^^^^^^^^^^^^^^^^^^^^^^^
  File "/home/airflow/.local/lib/python3.12/site-packages/airflow/operators/python.py", line 252, in execute_callable
    return self.python_callable(*self.op_args, **self.op_kwargs)
           ^^^^^^^^^^^^^^^^^^^^^^^^^^^^^^^^^^^^^^^^^^^^^^^^^^^^^
  File "/opt/airflow/dags/ingestion/api_fetcher/fetch_random_user.py", line 6, in fetch_random_user
    resp.raise_for_status()
  File "/home/airflow/.local/lib/python3.12/site-packages/requests/models.py", line 1021, in raise_for_status
    raise HTTPError(http_error_msg, response=self)
requests.exceptions.HTTPError: 502 Server Error: Bad Gateway for url: https://randomuser.me/api/
[2025-04-28T14:36:55.761+0000] {taskinstance.py:1206} INFO - Marking task as FAILED. dag_id=random_user_pipeline, task_id=fetch_random_user, run_id=manual__2025-04-28T14:31:31.683770+00:00, execution_date=20250428T143131, start_date=20250428T143646, end_date=20250428T143655
[2025-04-28T14:36:55.778+0000] {standard_task_runner.py:110} ERROR - Failed to execute job 6 for task fetch_random_user (502 Server Error: Bad Gateway for url: https://randomuser.me/api/; 260)
[2025-04-28T14:36:55.796+0000] {local_task_job_runner.py:240} INFO - Task exited with return code 1
[2025-04-28T14:36:56.069+0000] {taskinstance.py:3503} INFO - 0 downstream tasks scheduled from follow-on schedule check
[2025-04-28T14:36:56.075+0000] {local_task_job_runner.py:222} INFO - ::endgroup::
