[2025-04-28T16:18:29.271+0000] {local_task_job_runner.py:120} INFO - ::group::Pre task execution logs
[2025-04-28T16:18:29.531+0000] {taskinstance.py:2076} INFO - Dependencies all met for dep_context=non-requeueable deps ti=<TaskInstance: random_user_pipeline.insert_postgres manual__2025-04-28T16:08:33.804655+00:00 [queued]>
[2025-04-28T16:18:29.544+0000] {taskinstance.py:2076} INFO - Dependencies all met for dep_context=requeueable deps ti=<TaskInstance: random_user_pipeline.insert_postgres manual__2025-04-28T16:08:33.804655+00:00 [queued]>
[2025-04-28T16:18:29.545+0000] {taskinstance.py:2306} INFO - Starting attempt 2 of 2
[2025-04-28T16:18:29.566+0000] {taskinstance.py:2330} INFO - Executing <Task(PythonOperator): insert_postgres> on 2025-04-28 16:08:33.804655+00:00
[2025-04-28T16:18:29.573+0000] {standard_task_runner.py:90} INFO - Running: ['airflow', 'tasks', 'run', 'random_user_pipeline', 'insert_***', 'manual__2025-04-28T16:08:33.804655+00:00', '--job-id', '89', '--raw', '--subdir', 'DAGS_FOLDER/random_user_pipeline.py', '--cfg-path', '/tmp/tmp95jdf_31']
[2025-04-28T16:18:29.576+0000] {standard_task_runner.py:91} INFO - Job 89: Subtask insert_***
[2025-04-28T16:18:29.577+0000] {logging_mixin.py:188} WARNING - /home/airflow/.local/lib/python3.12/site-packages/airflow/task/task_runner/standard_task_runner.py:61 DeprecationWarning: This process (pid=186) is multi-threaded, use of fork() may lead to deadlocks in the child.
[2025-04-28T16:18:29.578+0000] {standard_task_runner.py:63} INFO - Started process 189 to run task
[2025-04-28T16:18:30.363+0000] {task_command.py:426} INFO - Running <TaskInstance: random_user_pipeline.insert_postgres manual__2025-04-28T16:08:33.804655+00:00 [running]> on host 03e87209dbec
[2025-04-28T16:18:31.800+0000] {taskinstance.py:2648} INFO - Exporting env vars: AIRFLOW_CTX_DAG_OWNER='airflow' AIRFLOW_CTX_DAG_ID='random_user_pipeline' AIRFLOW_CTX_TASK_ID='insert_***' AIRFLOW_CTX_EXECUTION_DATE='2025-04-28T16:08:33.804655+00:00' AIRFLOW_CTX_TRY_NUMBER='2' AIRFLOW_CTX_DAG_RUN_ID='manual__2025-04-28T16:08:33.804655+00:00'
[2025-04-28T16:18:31.801+0000] {taskinstance.py:430} INFO - ::endgroup::
[2025-04-28T16:18:32.134+0000] {taskinstance.py:441} INFO - ::group::Post task execution logs
[2025-04-28T16:18:32.135+0000] {taskinstance.py:2905} ERROR - Task failed with exception
Traceback (most recent call last):
  File "/home/airflow/.local/lib/python3.12/site-packages/airflow/models/taskinstance.py", line 465, in _execute_task
    result = _execute_callable(context=context, **execute_callable_kwargs)
             ^^^^^^^^^^^^^^^^^^^^^^^^^^^^^^^^^^^^^^^^^^^^^^^^^^^^^^^^^^^^^
  File "/home/airflow/.local/lib/python3.12/site-packages/airflow/models/taskinstance.py", line 432, in _execute_callable
    return execute_callable(context=context, **execute_callable_kwargs)
           ^^^^^^^^^^^^^^^^^^^^^^^^^^^^^^^^^^^^^^^^^^^^^^^^^^^^^^^^^^^^
  File "/home/airflow/.local/lib/python3.12/site-packages/airflow/models/baseoperator.py", line 401, in wrapper
    return func(self, *args, **kwargs)
           ^^^^^^^^^^^^^^^^^^^^^^^^^^^
  File "/home/airflow/.local/lib/python3.12/site-packages/airflow/operators/python.py", line 235, in execute
    return_value = self.execute_callable()
                   ^^^^^^^^^^^^^^^^^^^^^^^
  File "/home/airflow/.local/lib/python3.12/site-packages/airflow/operators/python.py", line 252, in execute_callable
    return self.python_callable(*self.op_args, **self.op_kwargs)
           ^^^^^^^^^^^^^^^^^^^^^^^^^^^^^^^^^^^^^^^^^^^^^^^^^^^^^
  File "/opt/airflow/dags/storage/postgres_loader/write_to_postgres.py", line 14, in write_to_postgres
    products = response_data.get('data', [])
               ^^^^^^^^^^^^^^^^^
AttributeError: 'str' object has no attribute 'get'
[2025-04-28T16:18:32.347+0000] {taskinstance.py:1206} INFO - Marking task as FAILED. dag_id=random_user_pipeline, task_id=insert_***, run_id=manual__2025-04-28T16:08:33.804655+00:00, execution_date=20250428T160833, start_date=20250428T161829, end_date=20250428T161832
[2025-04-28T16:18:32.370+0000] {standard_task_runner.py:110} ERROR - Failed to execute job 89 for task insert_*** ('str' object has no attribute 'get'; 189)
[2025-04-28T16:18:32.402+0000] {local_task_job_runner.py:240} INFO - Task exited with return code 1
[2025-04-28T16:18:32.626+0000] {taskinstance.py:3503} INFO - 0 downstream tasks scheduled from follow-on schedule check
[2025-04-28T16:18:32.629+0000] {local_task_job_runner.py:222} INFO - ::endgroup::
