[2025-04-28T15:35:10.227+0000] {local_task_job_runner.py:120} INFO - ::group::Pre task execution logs
[2025-04-28T15:35:10.755+0000] {taskinstance.py:2076} INFO - Dependencies all met for dep_context=non-requeueable deps ti=<TaskInstance: random_user_pipeline.insert_postgres manual__2025-04-28T15:35:00.971136+00:00 [queued]>
[2025-04-28T15:35:10.782+0000] {taskinstance.py:2076} INFO - Dependencies all met for dep_context=requeueable deps ti=<TaskInstance: random_user_pipeline.insert_postgres manual__2025-04-28T15:35:00.971136+00:00 [queued]>
[2025-04-28T15:35:10.783+0000] {taskinstance.py:2306} INFO - Starting attempt 1 of 2
[2025-04-28T15:35:10.818+0000] {taskinstance.py:2330} INFO - Executing <Task(PythonOperator): insert_postgres> on 2025-04-28 15:35:00.971136+00:00
[2025-04-28T15:35:10.828+0000] {standard_task_runner.py:90} INFO - Running: ['airflow', 'tasks', 'run', 'random_user_pipeline', 'insert_***', 'manual__2025-04-28T15:35:00.971136+00:00', '--job-id', '10', '--raw', '--subdir', 'DAGS_FOLDER/random_user_pipeline.py', '--cfg-path', '/tmp/tmpag5j1tdh']
[2025-04-28T15:35:10.834+0000] {standard_task_runner.py:91} INFO - Job 10: Subtask insert_***
[2025-04-28T15:35:10.835+0000] {logging_mixin.py:188} WARNING - /home/airflow/.local/lib/python3.12/site-packages/airflow/task/task_runner/standard_task_runner.py:61 DeprecationWarning: This process (pid=229) is multi-threaded, use of fork() may lead to deadlocks in the child.
[2025-04-28T15:35:10.836+0000] {standard_task_runner.py:63} INFO - Started process 230 to run task
[2025-04-28T15:35:12.179+0000] {task_command.py:426} INFO - Running <TaskInstance: random_user_pipeline.insert_postgres manual__2025-04-28T15:35:00.971136+00:00 [running]> on host b8c23e9f29a2
[2025-04-28T15:35:14.423+0000] {taskinstance.py:2648} INFO - Exporting env vars: AIRFLOW_CTX_DAG_OWNER='airflow' AIRFLOW_CTX_DAG_ID='random_user_pipeline' AIRFLOW_CTX_TASK_ID='insert_***' AIRFLOW_CTX_EXECUTION_DATE='2025-04-28T15:35:00.971136+00:00' AIRFLOW_CTX_TRY_NUMBER='1' AIRFLOW_CTX_DAG_RUN_ID='manual__2025-04-28T15:35:00.971136+00:00'
[2025-04-28T15:35:14.424+0000] {taskinstance.py:430} INFO - ::endgroup::
[2025-04-28T15:35:14.448+0000] {taskinstance.py:441} INFO - ::group::Post task execution logs
[2025-04-28T15:35:14.449+0000] {taskinstance.py:2905} ERROR - Task failed with exception
Traceback (most recent call last):
  File "/home/airflow/.local/lib/python3.12/site-packages/airflow/models/taskinstance.py", line 465, in _execute_task
    result = _execute_callable(context=context, **execute_callable_kwargs)
             ^^^^^^^^^^^^^^^^^^^^^^^^^^^^^^^^^^^^^^^^^^^^^^^^^^^^^^^^^^^^^
  File "/home/airflow/.local/lib/python3.12/site-packages/airflow/models/taskinstance.py", line 432, in _execute_callable
    return execute_callable(context=context, **execute_callable_kwargs)
           ^^^^^^^^^^^^^^^^^^^^^^^^^^^^^^^^^^^^^^^^^^^^^^^^^^^^^^^^^^^^
  File "/home/airflow/.local/lib/python3.12/site-packages/airflow/models/baseoperator.py", line 401, in wrapper
    return func(self, *args, **kwargs)
           ^^^^^^^^^^^^^^^^^^^^^^^^^^^
  File "/home/airflow/.local/lib/python3.12/site-packages/airflow/operators/python.py", line 235, in execute
    return_value = self.execute_callable()
                   ^^^^^^^^^^^^^^^^^^^^^^^
  File "/home/airflow/.local/lib/python3.12/site-packages/airflow/operators/python.py", line 252, in execute_callable
    return self.python_callable(*self.op_args, **self.op_kwargs)
           ^^^^^^^^^^^^^^^^^^^^^^^^^^^^^^^^^^^^^^^^^^^^^^^^^^^^^
  File "/opt/airflow/dags/storage/postgres_loader/write_to_postgres.py", line 12, in write_to_postgres
    data = data_json if isinstance(data_json, dict) else json.loads(data_json)
                                                         ^^^^^^^^^^^^^^^^^^^^^
  File "/usr/local/lib/python3.12/json/__init__.py", line 346, in loads
    return _default_decoder.decode(s)
           ^^^^^^^^^^^^^^^^^^^^^^^^^^
  File "/usr/local/lib/python3.12/json/decoder.py", line 337, in decode
    obj, end = self.raw_decode(s, idx=_w(s, 0).end())
               ^^^^^^^^^^^^^^^^^^^^^^^^^^^^^^^^^^^^^^
  File "/usr/local/lib/python3.12/json/decoder.py", line 355, in raw_decode
    raise JSONDecodeError("Expecting value", s, err.value) from None
json.decoder.JSONDecodeError: Expecting value: line 1 column 1 (char 0)
[2025-04-28T15:35:14.880+0000] {taskinstance.py:1206} INFO - Marking task as UP_FOR_RETRY. dag_id=random_user_pipeline, task_id=insert_***, run_id=manual__2025-04-28T15:35:00.971136+00:00, execution_date=20250428T153500, start_date=20250428T153510, end_date=20250428T153514
[2025-04-28T15:35:14.913+0000] {standard_task_runner.py:110} ERROR - Failed to execute job 10 for task insert_*** (Expecting value: line 1 column 1 (char 0); 230)
[2025-04-28T15:35:14.953+0000] {local_task_job_runner.py:240} INFO - Task exited with return code 1
[2025-04-28T15:35:15.389+0000] {taskinstance.py:3503} INFO - 0 downstream tasks scheduled from follow-on schedule check
[2025-04-28T15:35:15.392+0000] {local_task_job_runner.py:222} INFO - ::endgroup::
