[2025-05-22T12:59:56.264+0000] {local_task_job_runner.py:120} INFO - ::group::Pre task execution logs
[2025-05-22T12:59:56.575+0000] {taskinstance.py:2076} INFO - Dependencies all met for dep_context=non-requeueable deps ti=<TaskInstance: random_user_pipeline.log_ingestion_audit manual__2025-05-22T12:59:54.283035+00:00 [queued]>
[2025-05-22T12:59:56.586+0000] {taskinstance.py:2076} INFO - Dependencies all met for dep_context=requeueable deps ti=<TaskInstance: random_user_pipeline.log_ingestion_audit manual__2025-05-22T12:59:54.283035+00:00 [queued]>
[2025-05-22T12:59:56.587+0000] {taskinstance.py:2306} INFO - Starting attempt 1 of 2
[2025-05-22T12:59:56.611+0000] {taskinstance.py:2330} INFO - Executing <Task(PostgresOperator): log_ingestion_audit> on 2025-05-22 12:59:54.283035+00:00
[2025-05-22T12:59:56.617+0000] {logging_mixin.py:188} WARNING - /home/airflow/.local/lib/python3.12/site-packages/airflow/task/task_runner/standard_task_runner.py:61 DeprecationWarning: This process (pid=368) is multi-threaded, use of fork() may lead to deadlocks in the child.
[2025-05-22T12:59:56.619+0000] {standard_task_runner.py:63} INFO - Started process 369 to run task
[2025-05-22T12:59:56.618+0000] {standard_task_runner.py:90} INFO - Running: ['airflow', 'tasks', 'run', 'random_user_pipeline', 'log_ingestion_audit', 'manual__2025-05-22T12:59:54.283035+00:00', '--job-id', '410', '--raw', '--subdir', 'DAGS_FOLDER/random_user_pipeline.py', '--cfg-path', '/tmp/tmpni_y3h8h']
[2025-05-22T12:59:56.620+0000] {standard_task_runner.py:91} INFO - Job 410: Subtask log_ingestion_audit
[2025-05-22T12:59:57.485+0000] {task_command.py:426} INFO - Running <TaskInstance: random_user_pipeline.log_ingestion_audit manual__2025-05-22T12:59:54.283035+00:00 [running]> on host 9fdc869a03df
[2025-05-22T13:00:02.682+0000] {taskinstance.py:2648} INFO - Exporting env vars: AIRFLOW_CTX_DAG_EMAIL='papala.ramesh@quation.in,smilesoframs@gmail.com,ramesh.rams333@gmail.com' AIRFLOW_CTX_DAG_OWNER='airflow' AIRFLOW_CTX_DAG_ID='random_user_pipeline' AIRFLOW_CTX_TASK_ID='log_ingestion_audit' AIRFLOW_CTX_EXECUTION_DATE='2025-05-22T12:59:54.283035+00:00' AIRFLOW_CTX_TRY_NUMBER='1' AIRFLOW_CTX_DAG_RUN_ID='manual__2025-05-22T12:59:54.283035+00:00'
[2025-05-22T13:00:02.683+0000] {taskinstance.py:430} INFO - ::endgroup::
[2025-05-22T13:00:02.695+0000] {sql.py:276} INFO - Executing: -- Insert audit log
INSERT INTO ingestion_audit (
    ingestion_date,
    source,
    record_count,
    status,
    notes,
    retry_count,
    start_time,
    end_time
)
VALUES (
    '2025-05-22',
    'random_product_api',
    0,
    'unknown',
    'no notes',
    0,
    NULL,
    NULL
);
[2025-05-22T13:00:02.696+0000] {crypto.py:82} WARNING - empty cryptography key - values will not be stored encrypted.
[2025-05-22T13:00:02.697+0000] {base.py:84} INFO - Using connection ID '***_default' for task execution.
[2025-05-22T13:00:02.699+0000] {base.py:84} INFO - Using connection ID '***_default' for task execution.
[2025-05-22T13:00:03.076+0000] {sql.py:487} INFO - Running statement: -- Insert audit log
INSERT INTO ingestion_audit (
    ingestion_date,
    source,
    record_count,
    status,
    notes,
    retry_count,
    start_time,
    end_time
)
VALUES (
    '2025-05-22',
    'random_product_api',
    0,
    'unknown',
    'no notes',
    0,
    NULL,
    NULL
);, parameters: None
[2025-05-22T13:00:03.080+0000] {taskinstance.py:441} INFO - ::group::Post task execution logs
[2025-05-22T13:00:03.081+0000] {taskinstance.py:2905} ERROR - Task failed with exception
Traceback (most recent call last):
  File "/home/airflow/.local/lib/python3.12/site-packages/airflow/models/taskinstance.py", line 465, in _execute_task
    result = _execute_callable(context=context, **execute_callable_kwargs)
             ^^^^^^^^^^^^^^^^^^^^^^^^^^^^^^^^^^^^^^^^^^^^^^^^^^^^^^^^^^^^^
  File "/home/airflow/.local/lib/python3.12/site-packages/airflow/models/taskinstance.py", line 432, in _execute_callable
    return execute_callable(context=context, **execute_callable_kwargs)
           ^^^^^^^^^^^^^^^^^^^^^^^^^^^^^^^^^^^^^^^^^^^^^^^^^^^^^^^^^^^^
  File "/home/airflow/.local/lib/python3.12/site-packages/airflow/models/baseoperator.py", line 401, in wrapper
    return func(self, *args, **kwargs)
           ^^^^^^^^^^^^^^^^^^^^^^^^^^^
  File "/home/airflow/.local/lib/python3.12/site-packages/airflow/providers/common/sql/operators/sql.py", line 282, in execute
    output = hook.run(
             ^^^^^^^^^
  File "/home/airflow/.local/lib/python3.12/site-packages/airflow/providers/common/sql/hooks/sql.py", line 435, in run
    self._run_command(cur, sql_statement, parameters)
  File "/home/airflow/.local/lib/python3.12/site-packages/airflow/providers/common/sql/hooks/sql.py", line 492, in _run_command
    cur.execute(sql_statement)
psycopg2.errors.UndefinedTable: relation "ingestion_audit" does not exist
LINE 2: INSERT INTO ingestion_audit (
                    ^

[2025-05-22T13:00:03.434+0000] {taskinstance.py:1206} INFO - Marking task as UP_FOR_RETRY. dag_id=random_user_pipeline, task_id=log_ingestion_audit, run_id=manual__2025-05-22T12:59:54.283035+00:00, execution_date=20250522T125954, start_date=20250522T125956, end_date=20250522T130003
[2025-05-22T13:00:03.452+0000] {standard_task_runner.py:110} ERROR - Failed to execute job 410 for task log_ingestion_audit (relation "ingestion_audit" does not exist
LINE 2: INSERT INTO ingestion_audit (
                    ^
; 369)
[2025-05-22T13:00:03.461+0000] {local_task_job_runner.py:240} INFO - Task exited with return code 1
[2025-05-22T13:00:03.773+0000] {logging_mixin.py:188} WARNING - /home/airflow/.local/lib/python3.12/site-packages/airflow/models/baseoperator.py:1297 AirflowProviderDeprecationWarning: Call to deprecated class PostgresOperator. (Please use `airflow.providers.common.sql.operators.sql.SQLExecuteQueryOperator`.Also, you can provide `hook_params={'schema': <database>}`.)
[2025-05-22T13:00:03.790+0000] {taskinstance.py:3503} INFO - 0 downstream tasks scheduled from follow-on schedule check
[2025-05-22T13:00:03.793+0000] {local_task_job_runner.py:222} INFO - ::endgroup::
