[2025-05-22T05:40:53.655+0000] {local_task_job_runner.py:120} INFO - ::group::Pre task execution logs
[2025-05-22T05:40:54.320+0000] {taskinstance.py:2076} INFO - Dependencies all met for dep_context=non-requeueable deps ti=<TaskInstance: random_user_pipeline.branch_on_count manual__2025-05-22T05:40:44.862630+00:00 [queued]>
[2025-05-22T05:40:54.342+0000] {taskinstance.py:2076} INFO - Dependencies all met for dep_context=requeueable deps ti=<TaskInstance: random_user_pipeline.branch_on_count manual__2025-05-22T05:40:44.862630+00:00 [queued]>
[2025-05-22T05:40:54.345+0000] {taskinstance.py:2306} INFO - Starting attempt 1 of 2
[2025-05-22T05:40:54.377+0000] {taskinstance.py:2330} INFO - Executing <Task(BranchPythonOperator): branch_on_count> on 2025-05-22 05:40:44.862630+00:00
[2025-05-22T05:40:54.386+0000] {logging_mixin.py:188} WARNING - /home/airflow/.local/lib/python3.12/site-packages/airflow/task/task_runner/standard_task_runner.py:61 DeprecationWarning: This process (pid=383) is multi-threaded, use of fork() may lead to deadlocks in the child.
[2025-05-22T05:40:54.388+0000] {standard_task_runner.py:63} INFO - Started process 384 to run task
[2025-05-22T05:40:54.386+0000] {standard_task_runner.py:90} INFO - Running: ['airflow', 'tasks', 'run', 'random_user_pipeline', 'branch_on_count', 'manual__2025-05-22T05:40:44.862630+00:00', '--job-id', '382', '--raw', '--subdir', 'DAGS_FOLDER/random_user_pipeline.py', '--cfg-path', '/tmp/tmpdr8j1606']
[2025-05-22T05:40:54.389+0000] {standard_task_runner.py:91} INFO - Job 382: Subtask branch_on_count
[2025-05-22T05:40:55.790+0000] {task_command.py:426} INFO - Running <TaskInstance: random_user_pipeline.branch_on_count manual__2025-05-22T05:40:44.862630+00:00 [running]> on host cd3a1fee70a8
[2025-05-22T05:40:57.934+0000] {taskinstance.py:2648} INFO - Exporting env vars: AIRFLOW_CTX_DAG_EMAIL='papala.ramesh@quation.in,smilesoframs@gmail.com,ramesh.rams333@gmail.com' AIRFLOW_CTX_DAG_OWNER='airflow' AIRFLOW_CTX_DAG_ID='random_user_pipeline' AIRFLOW_CTX_TASK_ID='branch_on_count' AIRFLOW_CTX_EXECUTION_DATE='2025-05-22T05:40:44.862630+00:00' AIRFLOW_CTX_TRY_NUMBER='1' AIRFLOW_CTX_DAG_RUN_ID='manual__2025-05-22T05:40:44.862630+00:00'
[2025-05-22T05:40:57.936+0000] {taskinstance.py:430} INFO - ::endgroup::
[2025-05-22T05:40:57.957+0000] {baseoperator.py:400} WARNING - BranchPythonOperator.execute cannot be called outside TaskInstance!
[2025-05-22T05:40:57.964+0000] {crypto.py:82} WARNING - empty cryptography key - values will not be stored encrypted.
[2025-05-22T05:40:57.965+0000] {base.py:84} INFO - Using connection ID '***_default' for task execution.
[2025-05-22T05:40:58.345+0000] {sql.py:487} INFO - Running statement: SELECT COUNT(*) FROM users WHERE DATE(created_at) = CURRENT_DATE;
, parameters: None
[2025-05-22T05:40:58.350+0000] {taskinstance.py:441} INFO - ::group::Post task execution logs
[2025-05-22T05:40:58.352+0000] {taskinstance.py:2905} ERROR - Task failed with exception
Traceback (most recent call last):
  File "/home/airflow/.local/lib/python3.12/site-packages/airflow/models/taskinstance.py", line 465, in _execute_task
    result = _execute_callable(context=context, **execute_callable_kwargs)
             ^^^^^^^^^^^^^^^^^^^^^^^^^^^^^^^^^^^^^^^^^^^^^^^^^^^^^^^^^^^^^
  File "/home/airflow/.local/lib/python3.12/site-packages/airflow/models/taskinstance.py", line 432, in _execute_callable
    return execute_callable(context=context, **execute_callable_kwargs)
           ^^^^^^^^^^^^^^^^^^^^^^^^^^^^^^^^^^^^^^^^^^^^^^^^^^^^^^^^^^^^
  File "/home/airflow/.local/lib/python3.12/site-packages/airflow/models/baseoperator.py", line 401, in wrapper
    return func(self, *args, **kwargs)
           ^^^^^^^^^^^^^^^^^^^^^^^^^^^
  File "/home/airflow/.local/lib/python3.12/site-packages/airflow/operators/python.py", line 269, in execute
    return self.do_branch(context, super().execute(context))
                                   ^^^^^^^^^^^^^^^^^^^^^^^^
  File "/home/airflow/.local/lib/python3.12/site-packages/airflow/models/baseoperator.py", line 401, in wrapper
    return func(self, *args, **kwargs)
           ^^^^^^^^^^^^^^^^^^^^^^^^^^^
  File "/home/airflow/.local/lib/python3.12/site-packages/airflow/operators/python.py", line 235, in execute
    return_value = self.execute_callable()
                   ^^^^^^^^^^^^^^^^^^^^^^^
  File "/home/airflow/.local/lib/python3.12/site-packages/airflow/operators/python.py", line 252, in execute_callable
    return self.python_callable(*self.op_args, **self.op_kwargs)
           ^^^^^^^^^^^^^^^^^^^^^^^^^^^^^^^^^^^^^^^^^^^^^^^^^^^^^
  File "/opt/airflow/dags/utils/branch_decision.py", line 13, in evaluate_data_count
    result = hook.get_first(sql_query)
             ^^^^^^^^^^^^^^^^^^^^^^^^^
  File "/home/airflow/.local/lib/python3.12/site-packages/airflow/providers/common/sql/hooks/sql.py", line 312, in get_first
    return self.run(sql=sql, parameters=parameters, handler=fetch_one_handler)
           ^^^^^^^^^^^^^^^^^^^^^^^^^^^^^^^^^^^^^^^^^^^^^^^^^^^^^^^^^^^^^^^^^^^
  File "/home/airflow/.local/lib/python3.12/site-packages/airflow/providers/common/sql/hooks/sql.py", line 435, in run
    self._run_command(cur, sql_statement, parameters)
  File "/home/airflow/.local/lib/python3.12/site-packages/airflow/providers/common/sql/hooks/sql.py", line 492, in _run_command
    cur.execute(sql_statement)
psycopg2.errors.UndefinedTable: relation "users" does not exist
LINE 1: SELECT COUNT(*) FROM users WHERE DATE(created_at) = CURRENT_...
                             ^

[2025-05-22T05:40:58.806+0000] {taskinstance.py:1206} INFO - Marking task as UP_FOR_RETRY. dag_id=random_user_pipeline, task_id=branch_on_count, run_id=manual__2025-05-22T05:40:44.862630+00:00, execution_date=20250522T054044, start_date=20250522T054054, end_date=20250522T054058
[2025-05-22T05:40:58.858+0000] {standard_task_runner.py:110} ERROR - Failed to execute job 382 for task branch_on_count (relation "users" does not exist
LINE 1: SELECT COUNT(*) FROM users WHERE DATE(created_at) = CURRENT_...
                             ^
; 384)
[2025-05-22T05:40:58.908+0000] {local_task_job_runner.py:240} INFO - Task exited with return code 1
[2025-05-22T05:40:59.260+0000] {logging_mixin.py:188} WARNING - /home/airflow/.local/lib/python3.12/site-packages/airflow/models/baseoperator.py:1297 AirflowProviderDeprecationWarning: Call to deprecated class PostgresOperator. (Please use `airflow.providers.common.sql.operators.sql.SQLExecuteQueryOperator`.Also, you can provide `hook_params={'schema': <database>}`.)
[2025-05-22T05:40:59.287+0000] {taskinstance.py:3503} INFO - 0 downstream tasks scheduled from follow-on schedule check
[2025-05-22T05:40:59.291+0000] {local_task_job_runner.py:222} INFO - ::endgroup::
