[2025-05-04T03:22:15.605+0000] {local_task_job_runner.py:120} INFO - ::group::Pre task execution logs
[2025-05-04T03:22:19.059+0000] {taskinstance.py:2076} INFO - Dependencies all met for dep_context=non-requeueable deps ti=<TaskInstance: random_user_pipeline.fetch_random_product scheduled__2025-05-03T00:00:00+00:00 [queued]>
[2025-05-04T03:22:19.352+0000] {taskinstance.py:2076} INFO - Dependencies all met for dep_context=requeueable deps ti=<TaskInstance: random_user_pipeline.fetch_random_product scheduled__2025-05-03T00:00:00+00:00 [queued]>
[2025-05-04T03:22:19.438+0000] {taskinstance.py:2306} INFO - Starting attempt 1 of 2
[2025-05-04T03:22:20.010+0000] {taskinstance.py:2330} INFO - Executing <Task(PythonOperator): fetch_random_product> on 2025-05-03 00:00:00+00:00
[2025-05-04T03:22:20.102+0000] {standard_task_runner.py:90} INFO - Running: ['airflow', 'tasks', 'run', 'random_user_pipeline', 'fetch_random_product', 'scheduled__2025-05-03T00:00:00+00:00', '--job-id', '210', '--raw', '--subdir', 'DAGS_FOLDER/random_user_pipeline.py', '--cfg-path', '/tmp/tmp0j39cw5e']
[2025-05-04T03:22:20.161+0000] {standard_task_runner.py:91} INFO - Job 210: Subtask fetch_random_product
[2025-05-04T03:22:20.217+0000] {logging_mixin.py:188} WARNING - /home/airflow/.local/lib/python3.12/site-packages/airflow/task/task_runner/standard_task_runner.py:61 DeprecationWarning: This process (pid=4033) is multi-threaded, use of fork() may lead to deadlocks in the child.
[2025-05-04T03:22:20.275+0000] {standard_task_runner.py:63} INFO - Started process 4039 to run task
[2025-05-04T03:22:23.870+0000] {task_command.py:426} INFO - Running <TaskInstance: random_user_pipeline.fetch_random_product scheduled__2025-05-03T00:00:00+00:00 [running]> on host 4158771de208
[2025-05-04T03:22:25.468+0000] {taskinstance.py:2648} INFO - Exporting env vars: AIRFLOW_CTX_DAG_OWNER='airflow' AIRFLOW_CTX_DAG_ID='random_user_pipeline' AIRFLOW_CTX_TASK_ID='fetch_random_product' AIRFLOW_CTX_EXECUTION_DATE='2025-05-03T00:00:00+00:00' AIRFLOW_CTX_TRY_NUMBER='1' AIRFLOW_CTX_DAG_RUN_ID='scheduled__2025-05-03T00:00:00+00:00'
[2025-05-04T03:22:25.480+0000] {taskinstance.py:430} INFO - ::endgroup::
[2025-05-04T03:22:25.570+0000] {taskinstance.py:441} INFO - ::group::Post task execution logs
[2025-05-04T03:22:25.571+0000] {taskinstance.py:2905} ERROR - Task failed with exception
Traceback (most recent call last):
  File "/home/airflow/.local/lib/python3.12/site-packages/urllib3/connection.py", line 198, in _new_conn
    sock = connection.create_connection(
           ^^^^^^^^^^^^^^^^^^^^^^^^^^^^^
  File "/home/airflow/.local/lib/python3.12/site-packages/urllib3/util/connection.py", line 60, in create_connection
    for res in socket.getaddrinfo(host, port, family, socket.SOCK_STREAM):
               ^^^^^^^^^^^^^^^^^^^^^^^^^^^^^^^^^^^^^^^^^^^^^^^^^^^^^^^^^^
  File "/usr/local/lib/python3.12/socket.py", line 964, in getaddrinfo
    for res in _socket.getaddrinfo(host, port, family, type, proto, flags):
               ^^^^^^^^^^^^^^^^^^^^^^^^^^^^^^^^^^^^^^^^^^^^^^^^^^^^^^^^^^^
socket.gaierror: [Errno -2] Name or service not known

The above exception was the direct cause of the following exception:

Traceback (most recent call last):
  File "/home/airflow/.local/lib/python3.12/site-packages/urllib3/connectionpool.py", line 793, in urlopen
    response = self._make_request(
               ^^^^^^^^^^^^^^^^^^^
  File "/home/airflow/.local/lib/python3.12/site-packages/urllib3/connectionpool.py", line 491, in _make_request
    raise new_e
  File "/home/airflow/.local/lib/python3.12/site-packages/urllib3/connectionpool.py", line 467, in _make_request
    self._validate_conn(conn)
  File "/home/airflow/.local/lib/python3.12/site-packages/urllib3/connectionpool.py", line 1099, in _validate_conn
    conn.connect()
  File "/home/airflow/.local/lib/python3.12/site-packages/urllib3/connection.py", line 616, in connect
    self.sock = sock = self._new_conn()
                       ^^^^^^^^^^^^^^^^
  File "/home/airflow/.local/lib/python3.12/site-packages/urllib3/connection.py", line 205, in _new_conn
    raise NameResolutionError(self.host, self, e) from e
urllib3.exceptions.NameResolutionError: <urllib3.connection.HTTPSConnection object at 0x7f02f85800b0>: Failed to resolve 'fakerapi.it' ([Errno -2] Name or service not known)

The above exception was the direct cause of the following exception:

Traceback (most recent call last):
  File "/home/airflow/.local/lib/python3.12/site-packages/requests/adapters.py", line 486, in send
    resp = conn.urlopen(
           ^^^^^^^^^^^^^
  File "/home/airflow/.local/lib/python3.12/site-packages/urllib3/connectionpool.py", line 847, in urlopen
    retries = retries.increment(
              ^^^^^^^^^^^^^^^^^^
  File "/home/airflow/.local/lib/python3.12/site-packages/urllib3/util/retry.py", line 515, in increment
    raise MaxRetryError(_pool, url, reason) from reason  # type: ignore[arg-type]
    ^^^^^^^^^^^^^^^^^^^^^^^^^^^^^^^^^^^^^^^^^^^^^^^^^^^
urllib3.exceptions.MaxRetryError: HTTPSConnectionPool(host='fakerapi.it', port=443): Max retries exceeded with url: /api/v1/products?_quantity=10&_type=product (Caused by NameResolutionError("<urllib3.connection.HTTPSConnection object at 0x7f02f85800b0>: Failed to resolve 'fakerapi.it' ([Errno -2] Name or service not known)"))

During handling of the above exception, another exception occurred:

Traceback (most recent call last):
  File "/home/airflow/.local/lib/python3.12/site-packages/airflow/models/taskinstance.py", line 465, in _execute_task
    result = _execute_callable(context=context, **execute_callable_kwargs)
             ^^^^^^^^^^^^^^^^^^^^^^^^^^^^^^^^^^^^^^^^^^^^^^^^^^^^^^^^^^^^^
  File "/home/airflow/.local/lib/python3.12/site-packages/airflow/models/taskinstance.py", line 432, in _execute_callable
    return execute_callable(context=context, **execute_callable_kwargs)
           ^^^^^^^^^^^^^^^^^^^^^^^^^^^^^^^^^^^^^^^^^^^^^^^^^^^^^^^^^^^^
  File "/home/airflow/.local/lib/python3.12/site-packages/airflow/models/baseoperator.py", line 401, in wrapper
    return func(self, *args, **kwargs)
           ^^^^^^^^^^^^^^^^^^^^^^^^^^^
  File "/home/airflow/.local/lib/python3.12/site-packages/airflow/operators/python.py", line 235, in execute
    return_value = self.execute_callable()
                   ^^^^^^^^^^^^^^^^^^^^^^^
  File "/home/airflow/.local/lib/python3.12/site-packages/airflow/operators/python.py", line 252, in execute_callable
    return self.python_callable(*self.op_args, **self.op_kwargs)
           ^^^^^^^^^^^^^^^^^^^^^^^^^^^^^^^^^^^^^^^^^^^^^^^^^^^^^
  File "/opt/airflow/dags/ingestion/api_fetcher/fetch_random_user.py", line 10, in fetch_random_product
    resp = requests.get(url, params=params)
           ^^^^^^^^^^^^^^^^^^^^^^^^^^^^^^^^
  File "/home/airflow/.local/lib/python3.12/site-packages/requests/api.py", line 73, in get
    return request("get", url, params=params, **kwargs)
           ^^^^^^^^^^^^^^^^^^^^^^^^^^^^^^^^^^^^^^^^^^^^
  File "/home/airflow/.local/lib/python3.12/site-packages/requests/api.py", line 59, in request
    return session.request(method=method, url=url, **kwargs)
           ^^^^^^^^^^^^^^^^^^^^^^^^^^^^^^^^^^^^^^^^^^^^^^^^^
  File "/home/airflow/.local/lib/python3.12/site-packages/requests/sessions.py", line 589, in request
    resp = self.send(prep, **send_kwargs)
           ^^^^^^^^^^^^^^^^^^^^^^^^^^^^^^
  File "/home/airflow/.local/lib/python3.12/site-packages/requests/sessions.py", line 703, in send
    r = adapter.send(request, **kwargs)
        ^^^^^^^^^^^^^^^^^^^^^^^^^^^^^^^
  File "/home/airflow/.local/lib/python3.12/site-packages/requests/adapters.py", line 519, in send
    raise ConnectionError(e, request=request)
requests.exceptions.ConnectionError: HTTPSConnectionPool(host='fakerapi.it', port=443): Max retries exceeded with url: /api/v1/products?_quantity=10&_type=product (Caused by NameResolutionError("<urllib3.connection.HTTPSConnection object at 0x7f02f85800b0>: Failed to resolve 'fakerapi.it' ([Errno -2] Name or service not known)"))
[2025-05-04T03:22:26.350+0000] {taskinstance.py:1206} INFO - Marking task as UP_FOR_RETRY. dag_id=random_user_pipeline, task_id=fetch_random_product, run_id=scheduled__2025-05-03T00:00:00+00:00, execution_date=20250503T000000, start_date=20250504T032219, end_date=20250504T032226
[2025-05-04T03:22:26.576+0000] {standard_task_runner.py:110} ERROR - Failed to execute job 210 for task fetch_random_product (HTTPSConnectionPool(host='fakerapi.it', port=443): Max retries exceeded with url: /api/v1/products?_quantity=10&_type=product (Caused by NameResolutionError("<urllib3.connection.HTTPSConnection object at 0x7f02f85800b0>: Failed to resolve 'fakerapi.it' ([Errno -2] Name or service not known)")); 4039)
[2025-05-04T03:22:26.684+0000] {local_task_job_runner.py:240} INFO - Task exited with return code 1
[2025-05-04T03:22:27.285+0000] {taskinstance.py:3503} INFO - 0 downstream tasks scheduled from follow-on schedule check
[2025-05-04T03:22:27.290+0000] {local_task_job_runner.py:222} INFO - ::endgroup::
